Workbook

Sheet README
A1: CTE Explained: From Beginner to Advanced
A2: PostgreSQL practice workbook: roadmap, definitions, exercises and synthetic datasets
A4: How to use this workbook
A5: 1. Read the Definitions sheet to learn the vocabulary.
A6: 2. Follow the Roadmap sheet module by module (15 modules, Beginner to Advanced).
A7: 3. Load the data: run schema_and_data.sql in PostgreSQL (psql -d your_db -f schema_and_data.sql). The data sheets here mirror that script.
A8: 4. Solve each task on the Exercises sheet and save your answer in the solution file named in the last column.
A9: 5. Requirements: PostgreSQL 14 or newer (MATERIALIZED hints need 12+, SEARCH/CYCLE need 14+).
A11: Sheet index
A12: Sheet | B12: What it contains | C12: Rows
A13: Roadmap | B13: Table of contents: 15 modules, levels, topics, hours | C13: =COUNTA(Roadmap!B5:B19) -> 15
A14: Definitions | B14: CTE vocabulary, syntax and comparison with alternatives | C14: =COUNTA(Definitions!A5:A16) -> 12
A15: Exercises | B15: Every exercise with dataset, hint and solution file | C15: =COUNTA(Exercises!B5:B61) -> 57
A16: Data_Dictionary | B16: Tables, columns, types and constraints | C16: =COUNTA(Data_Dictionary!A5:A55) -> 51
A17: departments | B17: Departments (one has no employees) | C17: =COUNTA(departments!A2:A8) -> 7
A18: employees | B18: Employees with manager_id: 5-level hierarchy | C18: =COUNTA(employees!A2:A31) -> 30
A19: customers | B19: Customers (four have never ordered) | C19: =COUNTA(customers!A2:A31) -> 30
A20: categories | B20: Product category tree (3 levels) | C20: =COUNTA(categories!A2:A13) -> 12
A21: products | B21: Products linked to leaf categories | C21: =COUNTA(products!A2:A21) -> 20
A22: orders | B22: 120 orders, Jan 2025 to Jun 2026 | C22: =COUNTA(orders!A2:A121) -> 120
A23: order_items | B23: Order line items | C23: =COUNTA(order_items!A2:A287) -> 286
A24: routes | B24: Directed city graph containing cycles | C24: =COUNTA(routes!A2:A13) -> 12
A25: parts | B25: Bicycle parts and assemblies | C25: =COUNTA(parts!A2:A21) -> 20
A26: bom | B26: Bill of materials (parent, child, qty) | C26: =COUNTA(bom!A2:A21) -> 20
A27: customers_raw | B27: Messy records for cleaning and dedup | C27: =COUNTA(customers_raw!A2:A21) -> 20
A29: Level legend
A30: Beginner
A31: Intermediate
A32: Advanced
A34: Assumptions & notes
A35: • All records are synthetic (generated with a fixed random seed) and contain no real people or companies.
A36: • Route distances are approximate and illustrative; they are not for navigation.
A37: • Hours on the Roadmap are estimates (blue cells are editable inputs).
A38: • Empty helper tables (orders_archive, order_items_archive, salary_log, customers_clean) exist only in the SQL script and are described in Data_Dictionary.

Sheet Roadmap
A1: Roadmap (Table of Contents)
A2: Follow the modules in order. Exercise counts and hours are calculated from the Exercises sheet and this table.
A4: Module | B4: Title | C4: Level | D4: Topics covered | E4: You will be able to | F4: Datasets used | G4: Exercises | H4: Est. hours | I4: GitHub folder
A5: 0 | B5: Setup & SQL Refresher | C5: Beginner | D5: PostgreSQL install, loading the practice schema, SELECT / JOIN / GROUP BY / subquery refresher | E5: Run the schema, verify the data, and write the joins that every later module builds on | F5: all tables | G5: =COUNTIF(Exercises!$A$5:$A$200,A5) -> 3 | H5: 1.5 | I5: 00-setup
A6: 1 | B6: What Is a CTE? | C6: Beginner | D6: Definition, WITH syntax, naming, scope (one statement only) | E6: Define a CTE, explain why it exists, and rewrite a nested subquery as a named step | F6: employees, departments | G6: =COUNTIF(Exercises!$A$5:$A$200,A6) -> 3 | H6: 1.5 | I6: 01-what-is-a-cte
A7: 2 | B7: CTE vs Subquery vs View vs Temp Table | C7: Beginner | D7: Choosing the right tool, reuse of a CTE, reading query plans at a basic level | E7: Pick the right construct for a given reporting problem and justify it | F7: orders, order_items, products, customers | G7: =COUNTIF(Exercises!$A$5:$A$200,A7) -> 3 | H7: 1.5 | I7: 02-cte-vs-alternatives
A8: 3 | B8: Multiple & Chained CTEs | C8: Beginner | D8: Comma-separated CTEs, CTEs that reference earlier CTEs, joining CTEs, anti-joins | E8: Structure a multi-step analysis as a readable pipeline | F8: orders, order_items, customers | G8: =COUNTIF(Exercises!$A$5:$A$200,A8) -> 3 | H8: 2 | I8: 03-chained-ctes
A9: 4 | B9: CTEs for Aggregation & Joins | C9: Intermediate | D9: Pre-aggregation, the join fan-out trap, FILTER, cohort-style queries | E9: Avoid double counting and build correct KPI tables | F9: orders, order_items, products, customers | G9: =COUNTIF(Exercises!$A$5:$A$200,A9) -> 4 | H9: 2.5 | I9: 04-aggregation-patterns
A10: 5 | B10: CTEs + Window Functions | C10: Intermediate | D10: ROW_NUMBER / RANK, top-N per group, running totals, LAG for growth rates | E10: Answer ranking, trend and period-over-period questions | F10: orders, order_items, products, employees | G10: =COUNTIF(Exercises!$A$5:$A$200,A10) -> 5 | H10: 3 | I10: 05-window-functions
A11: 6 | B11: Data Cleaning & Deduplication | C11: Intermediate | D11: Normalising text, dedup with ROW_NUMBER, data-quality profiling | E11: Build a repeatable cleaning step and a data-quality summary | F11: customers_raw | G11: =COUNTIF(Exercises!$A$5:$A$200,A11) -> 3 | H11: 2 | I11: 06-data-cleaning
A12: 7 | B12: Materialization & the Optimizer | C12: Advanced | D12: MATERIALIZED / NOT MATERIALIZED (PG 12+), predicate pushdown, EXPLAIN ANALYZE | E12: Read plans and decide when a CTE helps or hurts performance | F12: orders, order_items | G12: =COUNTIF(Exercises!$A$5:$A$200,A12) -> 3 | H12: 2 | I12: 07-materialization
A13: 8 | B13: Recursive CTE Fundamentals | C13: Intermediate | D13: Anchor member, recursive member, UNION vs UNION ALL, termination, number and date series | E13: Write a recursive CTE safely and explain every iteration | F13: orders (calendar fill) | G13: =COUNTIF(Exercises!$A$5:$A$200,A13) -> 4 | H13: 2.5 | I13: 08-recursive-basics
A14: 9 | B14: Hierarchies: Org Charts & Category Trees | C14: Advanced | D14: Depth, path arrays, breadcrumbs, downward roll-ups, ordered tree output | E14: Traverse any parent-child table and produce BI-ready hierarchy output | F14: employees, categories, products, order_items | G14: =COUNTIF(Exercises!$A$5:$A$200,A14) -> 6 | H14: 3 | I14: 09-hierarchies
A15: 10 | B15: Graphs, Cycles & SEARCH/CYCLE | C15: Advanced | D15: Path enumeration, cycle detection, SEARCH BREADTH/DEPTH FIRST, CYCLE clause (PG 14+) | E15: Traverse graphs without infinite loops and know the limits of SQL for graph problems | F15: routes | G15: =COUNTIF(Exercises!$A$5:$A$200,A15) -> 5 | H15: 3 | I15: 10-graphs-and-cycles
A16: 11 | B16: Bill of Materials & Roll-ups | C16: Advanced | D16: Multiplying quantities down a tree, cost roll-up, where-used (upward) recursion | E16: Explode an assembly into its raw parts and compute rolled-up cost | F16: parts, bom | G16: =COUNTIF(Exercises!$A$5:$A$200,A16) -> 3 | H16: 2.5 | I16: 11-bill-of-materials
... A19: 14 | B19: Capstone Portfolio Projects | C19: Advanced | D19: End-to-end projects that combine all modules | E19: Ship portfolio-grade projects with documentation and tests | F19: all tables | G19: =COUNTIF(Exercises!$A$5:$A$200,A19) -> 4 | H19: 8 | I19: 14-capstones
B20: TOTAL | G20: =SUM(G5:G19) -> 57 | H20: =SUM(H5:H19) -> 40
A22: Note: hours (blue) are my estimates for an intermediate SQL user working through every exercise; adjust to your pace.

Sheet Exercises
A1: Exercises
A2: Each exercise maps to a module and a solution file you will commit to GitHub. Use the filters to focus on a level or dataset.
A4: Module | B4: Exercise ID | C4: Level | D4: Topic | E4: Business question / task | F4: Dataset(s) | G4: Hint / key concept | H4: Solution file
A5: 0 | B5: 00-01 | C5: Beginner | D5: Setup | E5: Run schema_and_data.sql and confirm the row count of every table. | F5: all | G5: SELECT COUNT(*) per table; the script ends with a UNION ALL check | H5: 00-setup/00-01.sql
A6: 0 | B6: 00-02 | C6: Beginner | D6: Refresher | E6: List every employee with department name and manager name (CEO included). | F6: employees, departments | G6: LEFT JOIN + self-join on manager_id | H6: 00-setup/00-02.sql
A7: 0 | B7: 00-03 | C7: Beginner | D7: Refresher | E7: Total revenue per product category for completed orders. | F7: orders, order_items, products, categories | G7: revenue = quantity * unit_price * (1 - discount) | H7: 00-setup/00-03.sql
A8: 1 | B8: 01-01 | C8: Beginner | D8: First CTE | E8: List employees earning more than the company average, computing the average in a CTE. | F8: employees | G8: WITH avg_salary AS (SELECT AVG(salary) ...) | H8: 01-what-is-a-cte/01-01.sql
A9: 1 | B9: 01-02 | C9: Beginner | D9: Readability | E9: Rewrite a nested-subquery query for departments with more than 3 employees as a CTE. | F9: employees, departments | G9: Name the CTE after what it contains | H9: 01-what-is-a-cte/01-02.sql
A10: 1 | B10: 01-03 | C10: Beginner | D10: Scope | E10: Prove a CTE only exists for one statement: reference it in a second statement and record the error. | F10: employees | G10: Expect: relation does not exist | H10: 01-what-is-a-cte/01-03.sql
A11: 2 | B11: 02-01 | C11: Beginner | D11: CTE vs subquery | E11: Find customers with more orders than the average customer. Write it as a subquery and as a CTE, then compare EXPLAIN output. | F11: orders, customers | G11: Count how many times each plan scans orders, and explain why | H11: 02-cte-vs-alternatives/02-01.sql
A12: 2 | B12: 02-02 | C12: Intermediate | D12: Reuse | E12: Show each category's share of total revenue, computing the grand total once in a CTE. | F12: orders, order_items, products, categories | G12: One CTE, referenced by a cross join or scalar subquery | H12: 02-cte-vs-alternatives/02-02.sql
A13: 2 | B13: 02-03 | C13: Intermediate | D13: Four containers | E13: Build the same monthly revenue report as a CTE, view, temp table and materialized view, prove all four match, then write a short decision note on when to use each. | F13: orders, order_items, products | G13: EXCEPT in both directions; drop the objects at the end | H13: 02-cte-vs-alternatives/02-03.sql
A14: 3 | B14: 03-01 | C14: Beginner | D14: Chaining | E14: Top 5 customers by revenue using three chained CTEs: order_totals, customer_totals, ranked. | F14: orders, order_items, customers | G14: Each CTE does one job | H14: 03-chained-ctes/03-01.sql
A15: 3 | B15: 03-02 | C15: Beginner | D15: Joining CTEs | E15: Show monthly revenue and monthly order count side by side from two independent CTEs. | F15: orders, order_items | G15: DATE_TRUNC('month', order_date) | H15: 03-chained-ctes/03-02.sql
A16: 3 | B16: 03-03 | C16: Beginner | D16: Anti-join | E16: Find customers who never placed an order. | F16: customers, orders | G16: LEFT JOIN ... IS NULL or NOT EXISTS | H16: 03-chained-ctes/03-03.sql
... A61: 14 | B61: 14-04 | C61: Advanced | D61: Capstone 4 | E61: Route planner write-up: graph search with cycle control, benchmarks and a discussion of limits. | F61: routes | G61: Include EXPLAIN ANALYZE evidence | H61: 14-capstones/14-04.sql

Sheet Definitions
A1: Definitions & Core Syntax
A2: Start here: the vocabulary you will use in every module.
A4: Term | B4: Definition | C4: Example
A5: CTE (Common Table Expression) | B5: A named, temporary result set defined with the WITH clause. It exists only for the duration of the single statement that follows it (SELECT, INSERT, UPDATE or DELETE). | C5: WITH dept_avg AS (SELECT dept_id, AVG(salary) AS avg_salary FROM employees GROUP BY dept_id) SELECT * FROM dept_avg;
A6: Basic syntax | B6: WITH name [(column list)] AS (query) main_query. Several CTEs are separated by commas, and later CTEs can reference earlier ones. | C6: WITH a AS (SELECT 1 AS x), b AS (SELECT x + 1 AS y FROM a) SELECT * FROM b;
A7: Why use a CTE | B7: Break complex logic into named, readable steps; reuse one result several times in a statement; make code easier to review and debug than deeply nested subqueries. | C7: Replace three levels of nested subqueries with three named CTEs.
A8: Scope | B8: A CTE is visible only to the statement it is attached to (and to CTEs defined after it in the same WITH). It is not stored and cannot be indexed. | C8: A second statement referencing dept_avg fails: relation does not exist.
A9: Recursive CTE | B9: WITH RECURSIVE lets a CTE reference itself. It is made of an anchor member and a recursive member joined by UNION or UNION ALL. Iteration stops when the recursive member returns no new rows. | C9: WITH RECURSIVE n(i) AS (SELECT 1 UNION ALL SELECT i + 1 FROM n WHERE i < 10) SELECT i FROM n;
A10: Anchor member | B10: The non-recursive starting query of a recursive CTE. It produces the first set of rows (for example the CEO or the root category). | C10: SELECT emp_id, 1 AS depth FROM employees WHERE manager_id IS NULL
A11: Recursive member | B11: The part that references the CTE itself and produces the next level of rows from the previous level. | C11: SELECT e.emp_id, t.depth + 1 FROM employees e JOIN tree t ON e.manager_id = t.emp_id
A12: UNION vs UNION ALL (recursive) | B12: UNION ALL keeps every row and is faster; UNION removes duplicates between iterations, which can stop some cycles but is slower and does not protect path-based queries. | C12: Prefer UNION ALL plus an explicit cycle guard.
A13: MATERIALIZED / NOT MATERIALIZED | B13: PostgreSQL 12+ hints. MATERIALIZED forces the CTE to be computed once and stored; NOT MATERIALIZED lets the planner inline it like a subquery. Before v12, CTEs were always materialized (an optimization fence). | C13: WITH x AS NOT MATERIALIZED (SELECT * FROM orders) SELECT * FROM x WHERE order_id = 5;
A14: Data-modifying CTE | B14: A CTE containing INSERT, UPDATE or DELETE, usually with RETURNING. It runs exactly once, whether or not the main query reads it, and all sub-statements share one snapshot. | C14: WITH moved AS (DELETE FROM orders WHERE status = 'cancelled' RETURNING *) INSERT INTO orders_archive SELECT * FROM moved;
A15: SEARCH clause (PG 14+) | B15: Adds a column that orders recursive output breadth-first or depth-first without hand-built path arrays. | C15: ... SEARCH DEPTH FIRST BY emp_id SET ordercol
A16: CYCLE clause (PG 14+) | B16: Detects cycles in recursive queries and marks or stops them automatically. | C16: ... CYCLE destination SET is_cycle USING path
A18: CTE vs alternatives
A19: Construct | B19: Lifetime | C19: Reusable across statements | D19: Indexable | E19: Best for | F19: Watch out for
A20: CTE (WITH) | B20: Single statement | C20: No | D20: No | E20: Readability, multi-step logic, recursion | F20: Not stored; recomputed each statement; can be inlined or materialized (PG 12+)
A21: Subquery | B21: Single statement | C21: No | D21: No | E21: Small, one-off filters or lookups | F21: Hard to read when deeply nested; cannot be referenced twice
A22: View | B22: Persistent definition | C22: Yes | D22: No (indexes go on base tables) | E22: Reusable business logic, security layer | F22: Runs the query every time; no stored data
A23: Temporary table | B23: Current session | C23: Within session | D23: Yes | E23: Large intermediate results reused many times | F23: Extra writes; must be created and managed; ANALYZE may be needed
A24: Materialized view | B24: Persistent data | C24: Yes | D24: Yes | E24: Expensive, read-heavy reports | F24: Stale until REFRESH; storage cost

Sheet Data_Dictionary
A1: Data Dictionary
A2: All data is synthetic and created for learning. Types and constraints match schema_and_data.sql.
A4: Table | B4: Column | C4: PostgreSQL type | D4: Constraint | E4: Description
A5: departments | B5: dept_id | C5: INT | D5: PRIMARY KEY | E5: Department identifier
A6: departments | B6: dept_name | C6: TEXT | D6: NOT NULL | E6: Department name (Marketing has no employees on purpose)
A7: departments | B7: location | C7: TEXT | E7: Office location
A8: employees | B8: emp_id | C8: INT | D8: PRIMARY KEY | E8: Employee identifier
A9: employees | B9: first_name | C9: TEXT | D9: NOT NULL | E9: First name
A10: employees | B10: last_name | C10: TEXT | D10: NOT NULL | E10: Last name
A11: employees | B11: job_title | C11: TEXT | E11: Job title
A12: employees | B12: dept_id | C12: INT | D12: REFERENCES departments(dept_id) | E12: FK to departments
A13: employees | B13: manager_id | C13: INT | D13: REFERENCES employees(emp_id) | E13: Self-reference; NULL for the CEO (root of the hierarchy, 5 levels deep)
A14: employees | B14: salary | C14: NUMERIC(10,2) | E14: Annual salary (synthetic)
A15: employees | B15: hire_date | C15: DATE | E15: Hire date
A16: customers | B16: customer_id | C16: INT | D16: PRIMARY KEY | E16: Customer identifier
A17: customers | B17: customer_name | C17: TEXT | D17: NOT NULL | E17: Customer name (synthetic)
A18: customers | B18: country | C18: TEXT | E18: Country
A19: customers | B19: segment | C19: TEXT | E19: Retail / SME / Corporate
A20: customers | B20: signup_date | C20: DATE | E20: Signup date; customers 27-30 have never ordered
A21: categories | B21: category_id | C21: INT | D21: PRIMARY KEY | E21: Category identifier
A22: categories | B22: category_name | C22: TEXT | D22: NOT NULL | E22: Category name
A23: categories | B23: parent_id | C23: INT | D23: REFERENCES categories(category_id) | E23: Self-reference; NULL for top-level categories (3 levels deep)
A24: products | B24: product_id | C24: INT | D24: PRIMARY KEY | E24: Product identifier
A25: products | B25: product_name | C25: TEXT | D25: NOT NULL | E25: Product name (fictional)
A26: products | B26: category_id | C26: INT | D26: REFERENCES categories(category_id) | E26: FK to a leaf category
A27: products | B27: unit_price | C27: NUMERIC(10,2) | E27: List price
A28: orders | B28: order_id | C28: INT | D28: PRIMARY KEY | E28: Order identifier (chronological)
A29: orders | B29: customer_id | C29: INT | D29: REFERENCES customers(customer_id) | E29: FK to customers
A30: orders | B30: order_date | C30: DATE | E30: Order date, 2025-01-01 to 2026-06-30
A31: orders | B31: status | C31: TEXT | E31: completed / shipped / pending / cancelled
A32: orders | B32: shipping_fee | C32: NUMERIC(6,2) | E32: Order-level fee; used for the join fan-out exercise
A33: order_items | B33: item_id | C33: INT | D33: PRIMARY KEY | E33: Line item identifier
A34: order_items | B34: order_id | C34: INT | D34: REFERENCES orders(order_id) | E34: FK to orders
A35: order_items | B35: product_id | C35: INT | D35: REFERENCES products(product_id) | E35: FK to products
A36: order_items | B36: quantity | C36: INT | E36: Units ordered
A37: order_items | B37: discount | C37: NUMERIC(3,2) | E37: Discount fraction, e.g. 0.10 = 10%
A38: routes | B38: route_id | C38: INT | D38: PRIMARY KEY | E38: Route identifier
A39: routes | B39: origin | C39: TEXT | D39: NOT NULL | E39: Start city (directed edge)
A40: routes | B40: destination | C40: TEXT | D40: NOT NULL | E40: End city
A41: routes | B41: distance_km | C41: INT | E41: Approximate illustrative distance; the graph contains cycles on purpose
...

Sheet departments
A1: dept_id | B1: dept_name | C1: location
A2: 1 | B2: Executive | C2: Nairobi
A3: 2 | B3: Engineering | C3: Nairobi
A4: 3 | B4: Sales | C4: Mombasa
A5: 4 | B5: Finance | C5: Nairobi
A6: 5 | B6: HR | C6: Nairobi
A7: 6 | B7: Data & Analytics | C7: Remote
A8: 7 | B8: Marketing | C8: Mombasa

Sheet employees
A1: emp_id | B1: first_name | C1: last_name | D1: job_title | E1: dept_id | F1: manager_id | G1: salary | H1: hire_date
A2: 1 | B2: Amina | C2: Hassan | D2: CEO | E2: 1 | G2: 250000 | H2: 42064
A3: 2 | B3: Brian | C3: Otieno | D3: VP Engineering | E3: 2 | F3: 1 | G3: 165000 | H3: 42536
A4: 3 | B4: Carla | C4: Mendes | D4: VP Sales | E4: 3 | F4: 1 | G4: 160000 | H4: 42614
A5: 4 | B5: David | C5: Kimani | D5: VP Finance | E5: 4 | F5: 1 | G5: 155000 | H5: 42745
A6: 5 | B6: Elena | C6: Petrova | D6: VP HR | E6: 5 | F6: 1 | G6: 150000 | H6: 43192
A7: 6 | B7: Farid | C7: Rahman | D7: VP Data & Analytics | E7: 6 | F7: 1 | G7: 160000 | H7: 43514
A8: 7 | B8: Grace | C8: Wanjiru | D8: Engineering Manager | E8: 2 | F8: 2 | G8: 105000 | H8: 43332
A9: 8 | B9: Hassan | C9: Ali | D9: Engineering Manager | E9: 2 | F9: 2 | G9: 102000 | H9: 43591
A10: 9 | B10: Irene | C10: Achieng | D10: Sales Manager | E10: 3 | F10: 3 | G10: 95000 | H10: 43668
A11: 10 | B11: James | C11: Mwangi | D11: Sales Manager | E11: 3 | F11: 3 | G11: 92000 | H11: 43843
A12: 11 | B12: Kofi | C12: Mensah | D12: Finance Manager | E12: 4 | F12: 4 | G12: 98000 | H12: 43745
A13: 12 | B13: Lina | C13: Schmidt | D13: HR Manager | E13: 5 | F13: 5 | G13: 90000 | H13: 43892
A14: 13 | B14: Mohamed | C14: Yusuf | D14: Data Manager | E14: 6 | F14: 6 | G14: 108000 | H14: 43983
... A31: 30 | B31: Daniel | C31: Kiprop | D31: Junior Analyst | E31: 6 | F31: 26 | G31: 42000 | H31: 45537

Sheet customers
A1: customer_id | B1: customer_name | C1: country | D1: segment | E1: signup_date
A2: 1 | B2: Achieng Omondi | C2: Kenya | D2: SME | E2: 45581
A3: 2 | B3: Brian Ali | C3: Kenya | D3: Retail | E3: 45177
A4: 3 | B4: Chloe Brown | C4: United States | D4: Retail | E4: 45619
A5: 4 | B5: Dennis Okeke | C5: Tanzania | D5: Retail | E5: 45531
A6: 5 | B6: Esther Otieno | C6: Kenya | D6: Retail | E6: 45022
A7: 6 | B7: Farid Khan | C7: Kenya | D7: Corporate | E7: 45501
A8: 7 | B8: Grace Atieno | C8: Tanzania | D8: SME | E8: 45152
A9: 8 | B9: Hamza Mwende | C9: United States | D9: Retail | E9: 44933
A10: 9 | B10: Ines Cohen | C10: Tanzania | D10: SME | E10: 45641
A11: 10 | B11: Joseph Njoroge | C11: Kenya | D11: SME | E11: 45086
A12: 11 | B12: Kendi Mugo | C12: Kenya | D12: Retail | E12: 45031
A13: 12 | B13: Liam Wairimu | C13: United States | D13: SME | E13: 45294
... A31: 30 | B31: Diana Torres | C31: Tanzania | D31: SME | E31: 46164

Sheet categories
A1: category_id | B1: category_name | C1: parent_id
A2: 1 | B2: Electronics
A3: 2 | B3: Computers | C3: 1
A4: 3 | B4: Laptops | C4: 2
A5: 4 | B5: Desktops | C5: 2
A6: 5 | B6: Phones | C6: 1
A7: 6 | B7: Smartphones | C7: 5
A8: 7 | B8: Accessories | C8: 1
A9: 8 | B9: Office
A10: 9 | B10: Furniture | C10: 8
A11: 10 | B11: Chairs | C11: 9
A12: 11 | B12: Desks | C12: 9
A13: 12 | B13: Stationery | C13: 8

Sheet products
A1: product_id | B1: product_name | C1: category_id | D1: unit_price
A2: 1 | B2: ThinkBook 14 | C2: 3 | D2: 750
A3: 2 | B3: UltraSlim 13 | C3: 3 | D3: 1100
A4: 3 | B4: Workstation Pro 16 | C4: 3 | D4: 1800
A5: 4 | B5: Mini PC M1 | C5: 4 | D5: 450
A6: 5 | B6: Tower T5 | C6: 4 | D6: 900
A7: 6 | B7: Nova X1 | C7: 6 | D7: 600
A8: 7 | B8: Nova X1 Pro | C8: 6 | D8: 850
A9: 8 | B9: Pulse A3 | C9: 6 | D9: 250
A10: 9 | B10: Wireless Mouse | C10: 7 | D10: 25
A11: 10 | B11: Mechanical Keyboard | C11: 7 | D11: 80
A12: 11 | B12: USB-C Hub | C12: 7 | D12: 45
A13: 12 | B13: 27in Monitor | C13: 7 | D13: 300
... A21: 20 | B21: Pen Set | C21: 12 | D21: 8

Sheet orders
A1: order_id | B1: customer_id | C1: order_date | D1: status | E1: shipping_fee
A2: 1 | B2: 4 | C2: 45658 | D2: completed | E2: 5
A3: 2 | B3: 2 | C3: 45663 | D3: pending | E3: 0
A4: 3 | B4: 5 | C4: 45669 | D4: completed | E4: 0
A5: 4 | B5: 3 | C5: 45678 | D5: pending | E5: 15
A6: 5 | B6: 23 | C6: 45685 | D6: pending | E6: 0
A7: 6 | B7: 3 | C7: 45697 | D7: pending | E7: 5
A8: 7 | B8: 3 | C8: 45698 | D8: pending | E8: 5
A9: 8 | B9: 17 | C9: 45700 | D9: completed | E9: 15
A10: 9 | B10: 19 | C10: 45703 | D10: completed | E10: 5
A11: 10 | B11: 22 | C11: 45710 | D11: completed | E11: 15
A12: 11 | B12: 4 | C12: 45711 | D12: cancelled | E12: 10
A13: 12 | B13: 4 | C13: 45713 | D13: completed | E13: 0
... A121: 120 | B121: 18 | C121: 46203 | D121: shipped | E121: 5

Sheet order_items
A1: item_id | B1: order_id | C1: product_id | D1: quantity | E1: discount
A2: 1 | B2: 1 | C2: 3 | D2: 1 | E2: 0.05
A3: 2 | B3: 1 | C3: 17 | D3: 4 | E3: 0
A4: 3 | B4: 1 | C4: 11 | D4: 4 | E4: 0
A5: 4 | B5: 2 | C5: 5 | D5: 3 | E5: 0
A6: 5 | B6: 2 | C6: 14 | D6: 5 | E6: 0.1
A7: 6 | B7: 2 | C7: 6 | D7: 2 | E7: 0.05
A8: 7 | B8: 2 | C8: 17 | D8: 4 | E8: 0.1
A9: 8 | B9: 3 | C9: 11 | D9: 3 | E9: 0.05
A10: 9 | B10: 3 | C10: 8 | D10: 2 | E10: 0.05
A11: 10 | B11: 3 | C11: 3 | D11: 3 | E11: 0.1
A12: 11 | B12: 4 | C12: 11 | D12: 2 | E12: 0.05
A13: 12 | B13: 4 | C13: 1 | D13: 1 | E13: 0
... A287: 286 | B287: 120 | C287: 17 | D287: 3 | E287: 0

Sheet routes
A1: route_id | B1: origin | C1: destination | D1: distance_km
A2: 1 | B2: Nairobi | C2: Nakuru | D2: 160
A3: 2 | B3: Nakuru | C3: Eldoret | D3: 150
A4: 3 | B4: Eldoret | C4: Kampala | D4: 400
A5: 4 | B5: Nairobi | C5: Mombasa | D5: 480
A6: 5 | B6: Mombasa | C6: Dar es Salaam | D6: 530
A7: 6 | B7: Nairobi | C7: Arusha | D7: 270
A8: 7 | B8: Arusha | C8: Dar es Salaam | D8: 630
A9: 8 | B9: Nakuru | C9: Kisumu | D9: 180
A10: 9 | B10: Kisumu | C10: Kampala | D10: 380
A11: 10 | B11: Kampala | C11: Kigali | D11: 510
A12: 11 | B12: Kampala | C12: Nairobi | D12: 650
A13: 12 | B13: Dar es Salaam | C13: Nairobi | D13: 880

Sheet parts
A1: part_id | B1: part_name | C1: unit_cost
A2: 1 | B2: Bicycle
A3: 2 | B3: Frame
A4: 3 | B4: Wheel Assembly
A5: 4 | B5: Drivetrain
A6: 5 | B6: Handlebar Assembly
A7: 6 | B7: Rim | C7: 18
A8: 7 | B8: Tire | C8: 12
A9: 8 | B9: Spoke | C9: 0.25
A10: 9 | B10: Hub | C10: 15
A11: 10 | B11: Chain | C11: 9
A12: 11 | B12: Crankset
A13: 12 | B13: Pedal | C13: 6
A14: 13 | B14: Rear Cassette | C14: 14
A15: 14 | B15: Handlebar | C15: 11
A16: 15 | B16: Grip | C16: 2
A17: 16 | B17: Brake Lever | C17: 7
A18: 17 | B18: Bolt | C18: 0.1
A19: 18 | B19: Frame Tube Set | C19: 60
A20: 19 | B20: Crank Arm | C20: 10
A21: 20 | B21: Chainring | C21: 8

Sheet bom
A1: assembly_id | B1: component_id | C1: qty
A2: 1 | B2: 2 | C2: 1
A3: 1 | B3: 3 | C3: 2
A4: 1 | B4: 4 | C4: 1
A5: 1 | B5: 5 | C5: 1
A6: 2 | B6: 18 | C6: 1
A7: 2 | B7: 17 | C7: 8
A8: 3 | B8: 6 | C8: 1
A9: 3 | B9: 7 | C9: 1
A10: 3 | B10: 8 | C10: 32
A11: 3 | B11: 9 | C11: 1
A12: 4 | B12: 10 | C12: 1
A13: 4 | B13: 11 | C13: 1
... A21: 5 | B21: 16 | C21: 2

Sheet customers_raw
A1: raw_id | B1: full_name | C1: email | D1: loaded_at
A2: 1 | B2: Alice Mwangi | C2: alice.mwangi@example.com | D2: 46027.333
A3: 2 | B3: alice mwangi | C3: Alice.Mwangi@Example.com | D3: 46063.396
A4: 3 | B4: Brian Otieno | C4: brian.otieno@example.com | D4: 46028.333
A5: 4 | B5: Brian Otieno | C5: BRIAN.OTIENO@EXAMPLE.COM | D5: 46082.469
A6: 5 | B6: Carol Njeri | C6: carol.njeri@example.com | D6: 46029.333
A7: 6 | B7: Daniel Kiprop | C7: daniel.kiprop@example.com | D7: 46030.333
A8: 7 | B8: Daniel Kiprop | C8: daniel.kiprop@example.com | D8: 46061.333
A9: 8 | B9: Esther Wafula | C9: esther.wafula@example.com | D9: 46031.333
A10: 9 | C10: unknown@example.com | D10: 46032.333
A11: 10 | B11: Farah Ahmed | C11: farah.ahmed@example | D11: 46033.333
A12: 11 | B12: George Ouma | D12: 46034.333
A13: 12 | B13: Hannah Schmidt | C13: hannah.schmidt@example.com | D13: 46035.333
A14: 13 | B14: hannah schmidt | C14: Hannah.Schmidt@example.com | D14: 46095.698
A15: 14 | B15: Ibrahim Musa | C15: ibrahim.musa@example.com | D15: 46037.333
A16: 15 | B16: Julia Santos | C16: julia.santos@example.com | D16: 46038.333
A17: 16 | B17: Kevin Mutua | C17: kevin.mutua@example.com | D17: 46039.333
A18: 17 | B18: Kevin Mutua | C18: kevin.mutua@example.com | D18: 46070.333
A19: 18 | B19: Linda Achieng | C19: linda.achieng@example.com | D19: 46040.333
A20: 19 | B20: Mark Otieno | C20: mark.otieno@example.com | D20: 46041.333
A21: 20 | B21: Mark Otieno | C21: mark.otieno@example.com | D21: 46100.333
